<?xml version="1.0"?>
<robot name="oven">
  <link name="base">
    <inertial>
        <origin rpy="0 0 0" xyz="0 0 0"/>
        <mass value="0.0"/>
        <inertia ixx="2e-2" ixy="0" ixz="0" iyy="2e-2" iyz="0" izz="2e-2"/>
    </inertial>
    <visual>
      <geometry>
        <mesh filename="base.obj"/>
      </geometry>
    </visual>
    <collision>
      <geometry>
        <mesh filename="base.obj"/>
      </geometry>
      <surface>
           <bounce restitution_coefficient = "0.1"/>
      </surface>
    </collision>
  </link>
  <link name="top">
    <inertial>
        <origin rpy="0 0 0" xyz="0 0 0"/>
        <mass value="0.0"/>
        <inertia ixx="2e-2" ixy="0" ixz="0" iyy="2e-2" iyz="0" izz="2e-2"/>
    </inertial>
    <visual>
      <geometry>
        <mesh filename="top.obj"/>
      </geometry>
    </visual>
    <collision>
      <geometry>
        <mesh filename="top.obj"/>
      </geometry>
      <surface>
           <bounce restitution_coefficient = "0.1"/>
      </surface>
    </collision>
  </link>
  <link name="top_back">
    <inertial>
        <origin rpy="0 0 0" xyz="0 0 0"/>
        <mass value="0.0"/>
        <inertia ixx="2e-2" ixy="0" ixz="0" iyy="2e-2" iyz="0" izz="2e-2"/>
    </inertial>
    <visual>
      <geometry>
        <mesh filename="top_back.obj"/>
      </geometry>
    </visual>
    <collision>
      <geometry>
        <mesh filename="top_back.obj"/>
      </geometry>
      <surface>
           <bounce restitution_coefficient = "0.1"/>
      </surface>
    </collision>
  </link>
  <link name="top_base">
    <inertial>
        <origin rpy="0 0 0" xyz="0 0 0"/>
        <mass value="0.0"/>
        <inertia ixx="2e-2" ixy="0" ixz="0" iyy="2e-2" iyz="0" izz="2e-2"/>
    </inertial>
    <visual>
      <geometry>
        <mesh filename="top_base.obj"/>
      </geometry>
    </visual>
    <collision>
      <geometry>
        <mesh filename="top_base.obj"/>
      </geometry>
      <surface>
           <bounce restitution_coefficient = "0.1"/>
      </surface>
    </collision>
  </link>
  <link name="back">
    <inertial>
        <origin rpy="0 0 0" xyz="0 0 0"/>
        <mass value="0.0"/>
        <inertia ixx="2e-2" ixy="0" ixz="0" iyy="2e-2" iyz="0" izz="2e-2"/>
    </inertial>
    <visual>
      <geometry>
        <mesh filename="back.obj"/>
      </geometry>
    </visual>
    <collision>
      <geometry>
        <mesh filename="back.obj"/>
      </geometry>
      <surface>
           <bounce restitution_coefficient = "0.1"/>
      </surface>
    </collision>
  </link>
  <link name="wall_left">
    <inertial>
        <origin rpy="0 0 0" xyz="0 0 0"/>
        <mass value="0.0"/>
        <inertia ixx="2e-2" ixy="0" ixz="0" iyy="2e-2" iyz="0" izz="2e-2"/>
    </inertial>
    <visual>
      <geometry>
        <mesh filename="wall.obj"/>
      </geometry>
    </visual>
    <collision>
      <geometry>
        <mesh filename="wall.obj"/>
      </geometry>
      <surface>
           <bounce restitution_coefficient = "0.1"/>
      </surface>
    </collision>
  </link>
  <link name="wall_right">
    <inertial>
        <origin rpy="0 0 0" xyz="0 0 0"/>
        <mass value="0.0"/>
        <inertia ixx="2e-2" ixy="0" ixz="0" iyy="2e-2" iyz="0" izz="2e-2"/>
    </inertial>
    <visual>
      <geometry>
        <mesh filename="wall.obj"/>
      </geometry>
    </visual>
    <collision>
      <geometry>
        <mesh filename="wall.obj"/>
      </geometry>
      <surface>
           <bounce restitution_coefficient = "0.1"/>
      </surface>
    </collision>
  </link>
  <link name="shelf">
    <inertial>
        <origin rpy="0 0 0" xyz="0 0 0"/>
        <mass value="0.0"/>
        <inertia ixx="2e-2" ixy="0" ixz="0" iyy="2e-2" iyz="0" izz="2e-2"/>
    </inertial>
    <visual>
      <geometry>
        <mesh filename="shelf.obj"/>
      </geometry>
    </visual>
    <collision>
      <geometry>
        <mesh filename="shelf.obj"/>
      </geometry>
      <surface>
           <bounce restitution_coefficient = "0.1"/>
      </surface>
    </collision>
  </link>
  <link name="door">
    <inertial>
        <origin rpy="0 0 0" xyz="0 0 0"/>
        <mass value="0.01"/>
        <inertia ixx="2e-2" ixy="0" ixz="0" iyy="2e-2" iyz="0" izz="2e-2"/>
    </inertial>
    <visual>
      <origin xyz="0 0 0.4" rpy="0 0 0" />
      <geometry>
        <mesh filename="door.obj"/>
      </geometry>
    </visual>
    <collision>
      <origin xyz="0 0 0.4" rpy="0 0 0" />
      <geometry>
        <mesh filename="dummy.obj"/>
      </geometry>
      <surface>
           <bounce restitution_coefficient = "0.1"/>
      </surface>
    </collision>
  </link>
  <link name="handle">
    <inertial>
        <origin rpy="0 0 0" xyz="0 0 0"/>
        <mass value="0.001"/>
        <inertia ixx="2e-2" ixy="0" ixz="0" iyy="2e-2" iyz="0" izz="2e-2"/>
    </inertial>
    <visual>
      <geometry>
        <mesh filename="handle.obj"/>
      </geometry>
    </visual>
    <collision>
      <geometry>
        <mesh filename="dummy.obj"/>
      </geometry>
      <surface>
           <bounce restitution_coefficient = "0.1"/>
      </surface>
    </collision>
  </link>
  <link name="glass">
    <inertial>
        <origin rpy="0 0 0" xyz="0 0 0"/>
        <mass value="0.01"/>
        <inertia ixx="2e-2" ixy="0" ixz="0" iyy="2e-2" iyz="0" izz="2e-2"/>
    </inertial>
    <visual>
      <origin xyz="0 0 0" rpy="0 0 0" />
      <geometry>
        <mesh filename="glass.obj"/>
      </geometry>
    </visual>
    <collision>
      <origin xyz="0 0 0" rpy="0 0 0" />
      <geometry>
        <mesh filename="glass.obj"/>
      </geometry>
      <surface>
           <bounce restitution_coefficient = "0.1"/>
      </surface>
    </collision>
  </link>
  <joint name="base_to_top" type="fixed">
    <parent link="base"/>
    <child link="top"/>
    <origin rpy="0 0 0" xyz="0 0.068 1.205"/>
  </joint>
  <joint name="base_to_top_back" type="fixed">
    <parent link="base"/>
    <child link="top_back"/>
    <origin rpy="0 0 0" xyz="0 -0.60. 1.35"/>
  </joint>
  <joint name="base_to_top_base" type="fixed">
    <parent link="base"/>
    <child link="top_base"/>
    <origin rpy="0 0 0" xyz="0 0.076 1.263"/>
  </joint>
  <joint name="base_to_back" type="fixed">
    <parent link="base"/>
    <child link="back"/>
    <origin rpy="0 0 0" xyz="0 -0.601 0.53"/>
  </joint>
  <joint name="base_to_wall_left" type="fixed">
    <parent link="base"/>
    <child link="wall_left"/>
    <origin rpy="0 0 0" xyz="-1.101 0.033 0.626"/>
  </joint>
  <joint name="base_to_wall_right" type="fixed">
    <parent link="base"/>
    <child link="wall_right"/>
    <origin rpy="0 0 0" xyz="1.101 0.033 0.626"/>
  </joint>
  <joint name="base_to_shelf" type="fixed">
    <parent link="base"/>
    <child link="shelf"/>
    <origin rpy="0 0 0" xyz="0 0.031 0.311"/>
  </joint>
  <joint name="door_to_handle" type="fixed">
    <parent link="door"/>
    <child link="handle"/>
    <origin rpy="0 0 0" xyz="0 0.024 0.764"/>
  </joint>
  <joint name="door_to_glass" type="fixed">
    <parent link="door"/>
    <child link="glass"/>
    <origin rpy="0 0 0" xyz="0 0 0.411"/>
  </joint>
  <joint name="base_to_door" type="revolute">
    <axis xyz="1 0 0"/>
    <parent link="base"/>
    <child link="door"/>
    <origin rpy="0 0 0" xyz="0 0.678 0.213"/>
    <limit effort="1000.0" lower="-1.57" upper="0" velocity="1."/>
    <joint_properties damping="0.0" friction="0.0"/>
  </joint>
</robot>

